<?xml version="1.0"?>
<!-- created with Phobos 0.7 -->
  <robot name="exoter">

    <link name="body">
      <inertial>
        <origin xyz="-0.0405 0 0.14642" rpy="0 0 0"/>
        <mass value="15.0"/>
        <inertia ixx="0.346254" ixy="0" ixz="0" iyy="0.379962" iyz="0" izz="0.464019"/>
      </inertial>
      <visual name="visual_0_body">
        <origin xyz="-0.0405 0 0.11" rpy="0 0 0"/>
        <geometry>
          <mesh filename="../meshes/Body Base Vicon And Gps.obj" scale="1.0 1.0 1.0"/>
        </geometry>
        <material name="exoter_body"/>
      </visual>
      <collision name="collision_0_body">
        <origin xyz="-0.0405 0 0.14642" rpy="0 0 0"/>
        <geometry>
          <box size="0.446195 0.414879 0.32385"/>
        </geometry>
      </collision>
    </link>

    <link name="rear_bogie">
      <inertial>
        <origin xyz="0 -0.000402 -0.019861" rpy="0 0 0"/>
        <mass value="0.2"/>
        <inertia ixx="0.004019" ixy="0" ixz="0" iyy="4e-05" iyz="0" izz="0.004027"/>
      </inertial>
      <visual name="visual_0_rear_bogie">
        <origin xyz="0 0 -0.02" rpy="0 0 0"/>
        <geometry>
          <mesh filename="../meshes/Rear Bogie.obj" scale="1.0 1.0 1.0"/>
        </geometry>
        <material name="exoter_black"/>
      </visual>
      <collision name="collision_0_rear_bogie">
        <origin xyz="0 -0.000402 -0.019861" rpy="0 0 0"/>
        <geometry>
          <box size="0.038019 0.490083 0.030617"/>
        </geometry>
      </collision>
    </link>

    <link name="left_bogie">
      <inertial>
        <origin xyz="0 0 0" rpy="0 0 0"/>
        <mass value="0.2"/>
        <inertia ixx="2.7e-05" ixy="0" ixz="0" iyy="0.00129" iyz="0" izz="0.001301"/>
      </inertial>
      <visual name="visual_0_left_bogie">
        <origin xyz="0 0 0" rpy="0 0 0"/>
        <geometry>
          <mesh filename="../meshes/Lateral Bogie.obj" scale="1.0 1.0 1.0"/>
        </geometry>
        <material name="exoter_black"/>
      </visual>
      <collision name="collision_0_left_bogie">
        <origin xyz="0 0 0" rpy="0 0 0"/>
        <geometry>
          <box size="0.277325 0.033846 0.022002"/>
        </geometry>
      </collision>
    </link>

    <link name="right_bogie">
      <inertial>
        <origin xyz="0 0 0" rpy="0 0 0"/>
        <mass value="0.2"/>
        <inertia ixx="2.7e-05" ixy="0" ixz="0" iyy="0.00129" iyz="0" izz="0.001301"/>
      </inertial>
      <visual name="visual_0_right_bogie">
        <origin xyz="0 0 0" rpy="3.14 0 0"/>
        <geometry>
          <mesh filename="../meshes/Lateral Bogie.001.obj" scale="1.0 1.0 1.0"/>
        </geometry>
        <material name="exoter_black"/>
      </visual>
      <collision name="collision_0_right_bogie">
        <origin xyz="0 0 0" rpy="3.14 0 0"/>
        <geometry>
          <box size="0.277325 0.033846 0.022002"/>
        </geometry>
      </collision>
    </link>

    <link name="fl_hinge">
      <visual name="visual_0_fl_hinge">
        <origin xyz="0 0 0" rpy="0 0 0"/>
        <geometry>
          <mesh filename="../meshes/Hinge Front Middle.001.obj" scale="1.0 1.0 1.0"/>
        </geometry>
        <material name="exoter_black"/>
      </visual>
    </link>

    <link name="fr_hinge">
      <visual name="visual_0_fr_hinge">
        <origin xyz="0 0 0" rpy="3.14 0 0"/>
        <geometry>
          <mesh filename="../meshes/Hinge Front Middle.obj" scale="1.0 1.0 1.0"/>
        </geometry>
        <material name="exoter_black"/>
      </visual>
    </link>

    <link name="ml_hinge">
      <visual name="visual_0_ml_hinge">
        <origin xyz="0 0 0" rpy="0 3.14 0"/>
        <geometry>
          <mesh filename="../meshes/Hinge Front Middle.003.obj" scale="1.0 1.0 1.0"/>
        </geometry>
        <material name="exoter_black"/>
      </visual>
    </link>

    <link name="mr_hinge">
      <visual name="visual_0_mr_hinge">
        <origin xyz="0 0 0" rpy="-0.001593 0.001593 -3.141593"/>
        <geometry>
          <mesh filename="../meshes/Hinge Front Middle.002.obj" scale="1.0 1.0 1.0"/>
        </geometry>
        <material name="exoter_black"/>
      </visual>
    </link>

    <link name="rl_hinge">
      <visual name="visual_0_rl_hinge">
        <origin xyz="0 0 0" rpy="0 0 0"/>
        <geometry>
          <mesh filename="../meshes/Hinge Back Left.obj" scale="1.0 1.0 1.0"/>
        </geometry>
        <material name="exoter_black"/>
      </visual>
    </link>

    <link name="rr_hinge">
      <visual name="visual_0_rr_hinge">
        <origin xyz="0 0 0" rpy="0 0 0"/>
        <geometry>
          <mesh filename="../meshes/Hinge Back Right.obj" scale="1.0 1.0 1.0"/>
        </geometry>
        <material name="exoter_black"/>
      </visual>
    </link>

    <link name="fl_motor">
      <inertial>
        <origin xyz="0.018 -0.000136 0.003997" rpy="0 0 0"/>
        <mass value="0.5"/>
        <inertia ixx="0.000889" ixy="0" ixz="0" iyy="0.000702" iyz="0" izz="0.000817"/>
      </inertial>
      <visual name="visual_0_fl_motor">
        <origin xyz="0 0 0" rpy="0 0 0"/>
        <geometry>
          <mesh filename="../meshes/Motor Block Fl.obj" scale="1.0 1.0 1.0"/>
        </geometry>
        <material name="exoter_black"/>
      </visual>
      <collision name="collision_0_fl_motor">
        <origin xyz="0.018 -0.000136 0.003997" rpy="0 0 0"/>
        <geometry>
          <box size="0.086968 0.109773 0.096307"/>
        </geometry>
      </collision>
    </link>

    <link name="fr_motor">
      <inertial>
        <origin xyz="-0.018 -0.000136 0.003997" rpy="0 0 0"/>
        <mass value="0.5"/>
        <inertia ixx="0.000889" ixy="0" ixz="0" iyy="0.000702" iyz="0" izz="0.000817"/>
      </inertial>
      <visual name="visual_0_fr_motor">
        <origin xyz="0 0 0" rpy="0 0 0"/>
        <geometry>
          <mesh filename="../meshes/Motor Block Rl.obj" scale="1.0 1.0 1.0"/>
        </geometry>
        <material name="exoter_black"/>
      </visual>
      <collision name="collision_0_fr_motor">
        <origin xyz="-0.018 -0.000136 0.003997" rpy="0 0 0"/>
        <geometry>
          <box size="0.086968 0.109773 0.096307"/>
        </geometry>
      </collision>
    </link>

    <link name="rl_motor">
      <inertial>
        <origin xyz="-0.018 -0.000136 0.003997" rpy="0 0 0"/>
        <mass value="0.5"/>
        <inertia ixx="0.000889" ixy="0" ixz="0" iyy="0.000702" iyz="0" izz="0.000817"/>
      </inertial>
      <visual name="visual_0_rl_motor">
        <origin xyz="0 0 0" rpy="0 0 0"/>
        <geometry>
          <mesh filename="../meshes/Motor Block Rl.001.obj" scale="1.0 1.0 1.0"/>
        </geometry>
        <material name="exoter_black"/>
      </visual>
      <collision name="collision_0_rl_motor">
        <origin xyz="-0.018 -0.000136 0.003997" rpy="0 0 0"/>
        <geometry>
          <box size="0.086968 0.109773 0.096307"/>
        </geometry>
      </collision>
    </link>

    <link name="rr_motor">
      <inertial>
        <origin xyz="-0.018 0.000136 0.003997" rpy="0 0 0"/>
        <mass value="0.5"/>
        <inertia ixx="0.000889" ixy="0" ixz="0" iyy="0.000702" iyz="0" izz="0.000817"/>
      </inertial>
      <visual name="visual_0_rr_motor">
        <origin xyz="0 0 0" rpy="0 0 0"/>
        <geometry>
          <mesh filename="../meshes/Motor Block Rr.obj" scale="1.0 1.0 1.0"/>
        </geometry>
        <material name="exoter_black"/>
      </visual>
      <collision name="collision_0_rr_motor">
        <origin xyz="-0.018 0.000136 0.003997" rpy="0 0 0"/>
        <geometry>
          <box size="0.086968 0.109773 0.096307"/>
        </geometry>
      </collision>
    </link>

    <link name="ml_motor">
      <inertial>
        <origin xyz="0 0 -0.051" rpy="0 0 0"/>
        <mass value="0.5"/>
        <inertia ixx="0.002084" ixy="0" ixz="0" iyy="0.001697" iyz="0" izz="0.000612"/>
      </inertial>
      <visual name="visual_0_ml_motor">
        <origin xyz="0 0 0" rpy="0 0 0"/>
        <geometry>
          <mesh filename="../meshes/Motor Middle Left.obj" scale="1.0 1.0 1.0"/>
        </geometry>
        <material name="exoter_black"/>
      </visual>
      <collision name="collision_0_ml_motor">
        <origin xyz="0 0 -0.051" rpy="0 0 0"/>
        <geometry>
          <box size="0.051968 0.1095 0.194979"/>
        </geometry>
      </collision>
    </link>

    <link name="mr_motor">
      <inertial>
        <origin xyz="0 0 -0.051" rpy="0 0 0"/>
        <mass value="0.5"/>
        <inertia ixx="0.002084" ixy="0" ixz="0" iyy="0.001697" iyz="0" izz="0.000612"/>
      </inertial>
      <visual name="visual_0_mr_motor">
        <origin xyz="0 0 0" rpy="0 0 0"/>
        <geometry>
          <mesh filename="../meshes/Motor Middle Right.obj" scale="1.0 1.0 1.0"/>
        </geometry>
        <material name="exoter_black"/>
      </visual>
      <collision name="collision_0_mr_motor">
        <origin xyz="0 0 -0.051" rpy="0 0 0"/>
        <geometry>
          <box size="0.051968 0.1095 0.194979"/>
        </geometry>
      </collision>
    </link>

    <link name="fl_fork">
      <visual name="visual_0_fl_fork">
        <origin xyz="0 0 0" rpy="0 0 0"/>
        <geometry>
          <mesh filename="../meshes/Fork Left.obj" scale="1.0 1.0 1.0"/>
        </geometry>
        <material name="exoter_black"/>
      </visual>
    </link>

    <link name="fr_fork">
      <visual name="visual_0_fr_fork">
        <origin xyz="0 0 0" rpy="0 0 0"/>
        <geometry>
          <mesh filename="../meshes/Fork Right.001.obj" scale="1.0 1.0 1.0"/>
        </geometry>
        <material name="exoter_black"/>
      </visual>
    </link>

    <link name="rl_fork">
      <visual name="visual_0_rl_fork">
        <origin xyz="0 0 0" rpy="0 0 0"/>
        <geometry>
          <mesh filename="../meshes/Fork Left.001.obj" scale="1.0 1.0 1.0"/>
        </geometry>
        <material name="exoter_black"/>
      </visual>
    </link>

    <link name="rr_fork">
      <visual name="visual_0_rr_fork">
        <origin xyz="0 0 0" rpy="0 0 0"/>
        <geometry>
          <mesh filename="../meshes/Fork Right.obj" scale="1.0 1.0 1.0"/>
        </geometry>
        <material name="exoter_black"/>
      </visual>
    </link>

    <link name="fl_wheel">
      <inertial>
        <origin xyz="0 0 0" rpy="0 0 0"/>
        <mass value="0.3"/>
        <inertia ixx="0.000664" ixy="0" ixz="0" iyy="0.000664" iyz="0" izz="0.000664"/>
      </inertial>
      <visual name="visual_0_fl_wheel">
        <origin xyz="0 0 0" rpy="0 0 0"/>
        <geometry>
          <mesh filename="../meshes/Wheel.obj" scale="1.0 1.0 1.0"/>
        </geometry>
        <material name="exoter_white"/>
      </visual>
      <collision name="collision_0_fl_wheel">
        <origin xyz="0 0 0" rpy="0 0 0"/>
        <geometry>
          <sphere radius="0.074365"/>
        </geometry>
      </collision>
    </link>

    <link name="fr_wheel">
      <inertial>
        <origin xyz="0 0 0" rpy="0 0 0"/>
        <mass value="0.3"/>
        <inertia ixx="0.000664" ixy="0" ixz="0" iyy="0.000664" iyz="0" izz="0.000664"/>
      </inertial>
      <visual name="visual_0_fr_wheel">
        <origin xyz="0 0 0" rpy="3.14 0 0"/>
        <geometry>
          <mesh filename="../meshes/Wheel.obj" scale="1.0 1.0 1.0"/>
        </geometry>
        <material name="exoter_white"/>
      </visual>
      <collision name="collision_0_fr_wheel">
        <origin xyz="0 0 0" rpy="3.14 0 0"/>
        <geometry>
          <sphere radius="0.074365"/>
        </geometry>
      </collision>
    </link>

    <link name="ml_wheel">
      <inertial>
        <origin xyz="0 0 0" rpy="0 0 0"/>
        <mass value="0.3"/>
        <inertia ixx="0.000664" ixy="0" ixz="0" iyy="0.000664" iyz="0" izz="0.000664"/>
      </inertial>
      <visual name="visual_0_ml_wheel">
        <origin xyz="0 0 0" rpy="0 0 0"/>
        <geometry>
          <mesh filename="../meshes/Wheel.obj" scale="1.0 1.0 1.0"/>
        </geometry>
        <material name="exoter_white"/>
      </visual>
      <collision name="collision_0_ml_wheel">
        <origin xyz="0 0 0" rpy="0 0 0"/>
        <geometry>
          <sphere radius="0.074365"/>
        </geometry>
      </collision>
    </link>

    <link name="mr_wheel">
      <inertial>
        <origin xyz="0 0 0" rpy="0 0 0"/>
        <mass value="0.3"/>
        <inertia ixx="0.000664" ixy="0" ixz="0" iyy="0.000664" iyz="0" izz="0.000664"/>
      </inertial>
      <visual name="visual_0_mr_wheel">
        <origin xyz="0 0 0" rpy="3.14 0 0"/>
        <geometry>
          <mesh filename="../meshes/Wheel.obj" scale="1.0 1.0 1.0"/>
        </geometry>
        <material name="exoter_white"/>
      </visual>
      <collision name="collision_0_mr_wheel">
        <origin xyz="0 0 0" rpy="3.14 0 0"/>
        <geometry>
          <sphere radius="0.074365"/>
        </geometry>
      </collision>
    </link>

    <link name="rl_wheel">
      <inertial>
        <origin xyz="0 0 0" rpy="0 0 0"/>
        <mass value="0.3"/>
        <inertia ixx="0.000664" ixy="0" ixz="0" iyy="0.000664" iyz="0" izz="0.000664"/>
      </inertial>
      <visual name="visual_0_rl_wheel">
        <origin xyz="0 0 0" rpy="0 0 0"/>
        <geometry>
          <mesh filename="../meshes/Wheel.obj" scale="1.0 1.0 1.0"/>
        </geometry>
        <material name="exoter_white"/>
      </visual>
      <collision name="collision_0_rl_wheel">
        <origin xyz="0 0 0" rpy="0 0 0"/>
        <geometry>
          <sphere radius="0.074365"/>
        </geometry>
      </collision>
    </link>

    <link name="rr_wheel">
      <inertial>
        <origin xyz="0 0 0" rpy="0 0 0"/>
        <mass value="0.3"/>
        <inertia ixx="0.000664" ixy="0" ixz="0" iyy="0.000664" iyz="0" izz="0.000664"/>
      </inertial>
      <visual name="visual_0_rr_wheel">
        <origin xyz="0 0 0" rpy="3.14 0 0"/>
        <geometry>
          <mesh filename="../meshes/Wheel.obj" scale="1.0 1.0 1.0"/>
        </geometry>
        <material name="exoter_white"/>
      </visual>
      <collision name="collision_0_rr_wheel">
        <origin xyz="0 0 0" rpy="3.14 0 0"/>
        <geometry>
          <sphere radius="0.074365"/>
        </geometry>
      </collision>
    </link>

    <link name="mast_assembly">
      <inertial>
        <origin xyz="0.000625 -0.00014 0.302" rpy="0 0 0"/>
        <mass value="0.5"/>
        <inertia ixx="0.021904" ixy="0" ixz="0" iyy="0.021903" iyz="0" izz="3.6e-05"/>
      </inertial>
      <visual name="visual_0_mast_assembly">
        <origin xyz="0 0 0" rpy="0 0 0"/>
        <geometry>
          <mesh filename="../meshes/Mast Assembly.obj" scale="1.0 1.0 1.0"/>
        </geometry>
        <material name="exoter_black"/>
      </visual>
      <collision name="collision_0_mast_assembly">
        <origin xyz="0.000625 -0.00014 0.302" rpy="0 0 0"/>
        <geometry>
          <box size="0.020475 0.020879 0.724748"/>
        </geometry>
      </collision>
    </link>

    <link name="pan_drive">
      <visual name="visual_0_pan_drive">
        <origin xyz="0 0 0" rpy="0 0 0"/>
        <geometry>
          <mesh filename="../meshes/Pan Drive.obj" scale="1.0 1.0 1.0"/>
        </geometry>
        <material name="exoter_black"/>
      </visual>
    </link>

    <link name="tilt_drive">
      <visual name="visual_0_tilt_drive">
        <origin xyz="0 0 0" rpy="0 0 0"/>
        <geometry>
          <mesh filename="../meshes/Tilt Drive.obj" scale="1.0 1.0 1.0"/>
        </geometry>
        <material name="exoter_black"/>
      </visual>
    </link>

    <link name="camera_assembly">
      <inertial>
        <origin xyz="-0.011215 -0.001045 0.061" rpy="0 0 0"/>
        <mass value="0.7"/>
        <inertia ixx="0.00256" ixy="0" ixz="0" iyy="0.001447" iyz="0" izz="0.001769"/>
      </inertial>
      <visual name="visual_0_camera_assembly">
        <origin xyz="0 0 0" rpy="0 0 0"/>
        <geometry>
          <mesh filename="../meshes/Bb2 And Tof Camera.obj" scale="1.0 1.0 1.0"/>
        </geometry>
        <material name="exoter_white"/>
      </visual>
      <collision name="collision_0_camera_assembly">
        <origin xyz="-0.011215 -0.001045 0.061" rpy="0 0 0"/>
        <geometry>
          <box size="0.075013 0.157175 0.1385"/>
        </geometry>
      </collision>
    </link>

    <link name="camera_left">
    </link>

    <link name="camera_right">
    </link>

    <joint name="rear_passive" type="revolute">
      <origin xyz="-0.265 0 0" rpy="0 0 0"/>
      <parent link="body"/>
      <child link="rear_bogie"/>
      <axis xyz="1.0 0 0"/>
      <limit lower="-1.57" upper="1.57" effort="100.0" velocity="6.0"/>
    </joint>

    <joint name="right_passive" type="revolute">
      <origin xyz="0.1325 -0.223 0" rpy="0 0 0"/>
      <parent link="body"/>
      <child link="right_bogie"/>
      <axis xyz="0 1.0 0"/>
      <limit lower="-1.57" upper="1.57" effort="100.0" velocity="6.0"/>
    </joint>

    <joint name="left_passive" type="revolute">
      <origin xyz="0.1325 0.223 0" rpy="0 0 0"/>
      <parent link="body"/>
      <child link="left_bogie"/>
      <axis xyz="0 1.0 0"/>
      <limit lower="-1.57" upper="1.57" effort="1.0" velocity="6.0"/>
    </joint>

    <joint name="fl_mimic" type="revolute">
      <origin xyz="0.1325 0 0" rpy="0 0 0"/>
      <parent link="left_bogie"/>
      <child link="fl_hinge"/>
      <axis xyz="0 1.0 0"/>
      <limit lower="-1.57" upper="1.57" effort="200.0" velocity="6.0"/>
    </joint>

    <joint name="fr_mimic" type="revolute">
      <origin xyz="0.1325 0 0" rpy="0 0 0"/>
      <parent link="right_bogie"/>
      <child link="fr_hinge"/>
      <axis xyz="0 1.0 0"/>
      <limit lower="-1.57" upper="1.57" effort="100.0" velocity="6.0"/>
    </joint>

    <joint name="ml_mimic" type="revolute">
      <origin xyz="-0.1325 0 0" rpy="0 0 0"/>
      <parent link="left_bogie"/>
      <child link="ml_hinge"/>
      <axis xyz="0 1.0 0"/>
      <limit lower="-1.57" upper="1.57" effort="200.0" velocity="6.0"/>
    </joint>

    <joint name="mr_mimic" type="revolute">
      <origin xyz="-0.1325 0 0" rpy="0 0 0"/>
      <parent link="right_bogie"/>
      <child link="mr_hinge"/>
      <axis xyz="0 1.0 0"/>
      <limit lower="-1.57" upper="1.57" effort="100.0" velocity="6.0"/>
    </joint>

    <joint name="rl_mimic" type="revolute">
      <origin xyz="0 0.239 0" rpy="0 0 0"/>
      <parent link="rear_bogie"/>
      <child link="rl_hinge"/>
      <axis xyz="1.0 0 0"/>
      <limit lower="-1.57" upper="1.57" effort="100.0" velocity="6.0"/>
    </joint>

    <joint name="rr_mimic" type="revolute">
      <origin xyz="0 -0.239 0" rpy="0 0 0"/>
      <parent link="rear_bogie"/>
      <child link="rr_hinge"/>
      <axis xyz="1.0 0 0"/>
      <limit lower="-1.57" upper="1.57" effort="100.0" velocity="6.0"/>
    </joint>

    <joint name="fl_walking" type="revolute">
      <origin xyz="0 0.087 -0.005" rpy="0 0 0"/>
      <parent link="fl_hinge"/>
      <child link="fl_motor"/>
      <axis xyz="0 1.0 0"/>
      <limit lower="-1.57" upper="1.57" effort="100.0" velocity="6.0"/>
    </joint>

    <joint name="fr_walking" type="revolute">
      <origin xyz="0 -0.087 -0.005" rpy="0 0 0"/>
      <parent link="fr_hinge"/>
      <child link="fr_motor"/>
      <axis xyz="0 1.0 0"/>
      <limit lower="-1.57" upper="1.57" effort="100.0" velocity="6.0"/>
    </joint>

    <joint name="rl_walking" type="revolute">
      <origin xyz="0 0.071 -0.005" rpy="0 0 0"/>
      <parent link="rl_hinge"/>
      <child link="rl_motor"/>
      <axis xyz="0 1.0 0"/>
      <limit lower="-1.57" upper="1.57" effort="100.0" velocity="6.0"/>
    </joint>

    <joint name="rr_walking" type="revolute">
      <origin xyz="0 -0.071 -0.005" rpy="0 0 0"/>
      <parent link="rr_hinge"/>
      <child link="rr_motor"/>
      <axis xyz="0 1.0 0"/>
      <limit lower="-1.57" upper="1.57" effort="100.0" velocity="6.0"/>
    </joint>

    <joint name="ml_walking" type="revolute">
      <origin xyz="0 0.087 -0.005" rpy="0 0 0"/>
      <parent link="ml_hinge"/>
      <child link="ml_motor"/>
      <axis xyz="0 1.0 0"/>
      <limit lower="-1.57" upper="1.57" effort="100.0" velocity="6.0"/>
    </joint>

    <joint name="mr_walking" type="revolute">
      <origin xyz="0 -0.087 -0.005" rpy="0 0 0"/>
      <parent link="mr_hinge"/>
      <child link="mr_motor"/>
      <axis xyz="0 1.0 0"/>
      <limit lower="-1.57" upper="1.57" effort="100.0" velocity="6.0"/>
    </joint>

    <joint name="fl_steer" type="revolute">
      <origin xyz="0 0 -0.03" rpy="0 0 0"/>
      <parent link="fl_motor"/>
      <child link="fl_fork"/>
      <axis xyz="0 0 1.0"/>
      <limit lower="-1.57" upper="1.57" effort="100.0" velocity="6.0"/>
    </joint>

    <joint name="fr_steer" type="revolute">
      <origin xyz="0 0 -0.03" rpy="0 0 0"/>
      <parent link="fr_motor"/>
      <child link="fr_fork"/>
      <axis xyz="0 0 1.0"/>
      <limit lower="-1.57" upper="1.57" effort="100.0" velocity="6.0"/>
    </joint>

    <joint name="rl_steer" type="revolute">
      <origin xyz="0 0 -0.03" rpy="0 0 0"/>
      <parent link="rl_motor"/>
      <child link="rl_fork"/>
      <axis xyz="0 0 1.0"/>
      <limit lower="-1.57" upper="1.57" effort="100.0" velocity="6.0"/>
    </joint>

    <joint name="rr_steer" type="revolute">
      <origin xyz="0 0 -0.03" rpy="0 0 0"/>
      <parent link="rr_motor"/>
      <child link="rr_fork"/>
      <axis xyz="0 0 1.0"/>
      <limit lower="-1.57" upper="1.57" effort="100.0" velocity="6.0"/>
    </joint>

    <joint name="fl_drive" type="continuous">
      <origin xyz="0 0 -0.0953" rpy="0 0 0"/>
      <parent link="fl_fork"/>
      <child link="fl_wheel"/>
      <axis xyz="0 1.0 0"/>
      <limit effort="100" velocity="6.28"/>
    </joint>

    <joint name="fr_drive" type="continuous">
      <origin xyz="0 0 -0.0953" rpy="0 0 0"/>
      <parent link="fr_fork"/>
      <child link="fr_wheel"/>
      <axis xyz="0 1.0 0"/>
      <limit effort="100" velocity="6.28"/>
    </joint>

    <joint name="ml_drive" type="continuous">
      <origin xyz="0 0 -0.1253" rpy="0 0 0"/>
      <parent link="ml_motor"/>
      <child link="ml_wheel"/>
      <axis xyz="0 1.0 0"/>
      <limit effort="200.0" velocity="6.0"/>
    </joint>

    <joint name="mr_drive" type="continuous">
      <origin xyz="0 0 -0.1253" rpy="0 0 0"/>
      <parent link="mr_motor"/>
      <child link="mr_wheel"/>
      <axis xyz="0 1.0 0"/>
      <limit effort="100" velocity="6.28"/>
    </joint>

    <joint name="rl_drive" type="continuous">
      <origin xyz="0 0 -0.0953" rpy="0 0 0"/>
      <parent link="rl_fork"/>
      <child link="rl_wheel"/>
      <axis xyz="0 1.0 0"/>
      <limit effort="100" velocity="6.28"/>
    </joint>

    <joint name="rr_drive" type="continuous">
      <origin xyz="0 0 -0.0953" rpy="0 0 0"/>
      <parent link="rr_fork"/>
      <child link="rr_wheel"/>
      <axis xyz="0 1.0 0"/>
      <limit effort="100" velocity="6.28"/>
    </joint>

    <joint name="mast_joint" type="fixed">
      <origin xyz="0.076 0 0" rpy="0 0 0"/>
      <parent link="body"/>
      <child link="mast_assembly"/>
      <limit effort="100" velocity="6.28"/>
    </joint>

    <joint name="mast_top_joint" type="revolute">
      <origin xyz="0 0 0.64" rpy="0 0 0"/>
      <parent link="mast_assembly"/>
      <child link="pan_drive"/>
      <axis xyz="0 0 1.0"/>
      <limit lower="-1.57" upper="1.57" effort="100.0" velocity="6.0"/>
    </joint>

    <joint name="pan_joint" type="revolute">
      <origin xyz="0 0 0" rpy="0 0 0"/>
      <parent link="pan_drive"/>
      <child link="tilt_drive"/>
      <axis xyz="0 0 1.0"/>
      <limit lower="-1.57" upper="1.57" effort="100.0" velocity="6.0"/>
    </joint>

    <joint name="tilt_joint" type="revolute">
      <origin xyz="0 0 0.03" rpy="0 0 0"/>
      <parent link="tilt_drive"/>
      <child link="camera_assembly"/>
      <axis xyz="0 1.0 0"/>
      <limit lower="-1.57" upper="1.57" effort="100.0" velocity="6.0"/>
    </joint>

    <joint name="camera_left" type="fixed">
      <origin xyz="0.023272 0.058819 0.035426" rpy="0 -1e-06 0"/>
      <parent link="camera_assembly"/>
      <child link="camera_left"/>
    </joint>

    <joint name="camera_right" type="fixed">
      <origin xyz="0.023272 -0.061145 0.035426" rpy="0 -1e-06 0"/>
      <parent link="camera_assembly"/>
      <child link="camera_right"/>
    </joint>

    <material name="exoter_black">
      <color rgba="0 0 0 1.0"/>
    </material>

    <material name="exoter_body">
      <color rgba="0.649111 0.799172 1.0 1.0"/>
    </material>

    <material name="exoter_white">
      <color rgba="1.0 1.0 1.0 1.0"/>
    </material>

  </robot>
